schema_version: 1.2.0
id: CVE-2019-19275
aliases: []
modified: 2020-03-14T02:15Z
published: 2019-11-26T15:15Z
details: typed_ast 1.3.0 and 1.3.1 has an ast_for_arguments out-of-bounds read. An
  attacker with the ability to cause a Python interpreter to parse Python source (but
  not necessarily execute it) may be able to crash the interpreter process. This could
  be a concern, for example, in a web-based service that parses (but does not execute)
  Python code. (This issue also affected certain Python 3.8.0-alpha prereleases.)
severity:
- type: CVSS_V3
  score: 7.5
- type: CVSS_V2
  score: 5.0
affected:
- package:
    name: typed_ast
    cpe: cpe:2.3:a:python:typed_ast
- ranges:
  - type: GIT
    repo: https://github.com/python/cpython
    events:
    - introduced: '0'
    - fixed: a4d78362397fc3bced6ea80fbc7b5f4827aec55e
  - type: GIT
    repo: https://github.com/python/cpython
    events:
    - introduced: '0'
    - fixed: dcfcd146f8e6fc5c2fc16a4c192a0c5f5ca8c53c
  - type: GIT
    repo: https://github.com/python/typed_ast
    events:
    - introduced: '0'
    - fixed: 156afcb26c198e162504a57caddfe0acd9ed7dce
  - type: GIT
    repo: https://github.com/python/typed_ast
    events:
    - introduced: '0'
    - fixed: dc317ac9cff859aa84eeabe03fb5004982545b3b
- versions:
  - 1.3.0
  - 1.3.1
- database_specific:
    CWE:
    - CWE-125
    CVSS:
      Score: 7.5
      Severity: HIGH
      Code: CVSS:3.1/AV:N/AC:L/PR:N/UI:N/S:U/C:N/I:N/A:H
references:
- type: WEB
  url: https://lists.fedoraproject.org/archives/list/package-announce@lists.fedoraproject.org/message/LG5H4Q6LFVRX7SFXLBEJMNQFI4T5SCEA/
- type: FIX
  url: https://github.com/python/cpython/commit/a4d78362397fc3bced6ea80fbc7b5f4827aec55e
- type: FIX
  url: https://github.com/python/cpython/commit/dcfcd146f8e6fc5c2fc16a4c192a0c5f5ca8c53c
- type: FIX
  url: https://github.com/python/typed_ast/commit/156afcb26c198e162504a57caddfe0acd9ed7dce
- type: FIX
  url: https://github.com/python/typed_ast/commit/dc317ac9cff859aa84eeabe03fb5004982545b3b
- type: REPORT
  url: https://bugs.python.org/issue36495
